Workbook

Sheet SNP-AD-DEN
A1: id | B1: anio | C1: tipo_anp | D1: canal_origen | E1: nro_expediente | F1: estado | G1: nro_expediente_sunged | H1: id_universidad | I1: tipo_gestion | J1: codigo_local | K1: region | L1: provincia | M1: distrito | N1: direccion | O1: modelo | P1: cbc | Q1: indicador | R1: hechos_denunciados | S1: complejidad | T1: prioridad | U1: ultima_accion | V1: fecha_ultima_accion | W1: comentarios | X1: profesional_asignado | Y1: acciones | Z1: comprometido_plan_2026 | AA1: entrega_informe_fecha | AB1: entrega_informe_estado | AC1: revision_jefe_fecha | AD1: revision_jefe_estado | AE1: productos | AF1: inicio_anp_documento | AG1: inicio_anp_fecha_notif | AH1: inicio_anp_dias_habiles | AI1: inicio_anp_fecha_venc | AJ1: inicio_anp_dias_venc | AK1: inicio_anp_alerta_i | AL1: inicio_anp_alerta_ii | AM1: inicio_anp_estado | AN1: inicio_anp_observaciones | AO1: seg_anp_ultima_actuacion | AP1: seg_anp_fecha_entrega | AQ1: seg_anp_tipo_info | AR1: seg_anp_diferencia_dias | AS1: seg_anp_observaciones | AT1: seg_anp_tipo_solicitud | AU1: seg_anp_documento | AV1: seg_anp_fecha_notif | AW1: seg_anp_dias_habiles | AX1: seg_anp_fecha_venc | AY1: seg_anp_dias_venc | AZ1: seg_anp_alerta_i | BA1: seg_anp_alerta_ii | BB1: seg_anp_estado | BC1: seg_anp_observaciones
A2: 1 | B2: 2022 | C2: Accion Directa | D2: Correo electrónico | E2: AD-005-2022 | F2: Archivado/UDRA | H2: 29 | I2: Pública | J2: SL01, SL02 | K2: Apurimac | L2: Andahuaylas | M2: San Jerónimo (SL01) | Talavera de la Reyna (SL02) | N2: Av. José María Arguedas S/N (SL01) | Av. 28 de Julio N° 1103 (SL02) | O2: MLI | P2: III, V, VI | Q2: 19, 27 | R2: La acción directa se motiva ante la falta de evidencia sobre la implementación de ambientes de enseñanza (aulas, laboratorios y talleres) y adquisiciOn de equipamiento necesarios para la prestación del servicio educativo de los cursos desde el tercer año de estudios para los programas nuevos (Contabilidad, Educación Primaria Intercultural e Ingeniería Ambiental), así como incluye también indagaciones respecto a la disponibilidad del servicio de biblioteca. Esto fue advertido a través de un análisis previo realizado por la Dilic y tras el traslado de pronunciamientos de los Centros Federados de la UNJMA. | S2: ALTA | T2: 2 | U2: La Universidad presentó información del acta del 13/11/2025. | V2: 45974 | W2: Están vinculados 2 informes de RCRQ (Informe 0441-2021-SUNEDU-02-12 DEL 17.05.2021 e 1286-2021-SUNEDU-02-12 del 15.12.2021) relacionado con la ejecución de sus proyectos de inversión. Cuenta con 2 supervisiones de campo, 1 realizada en setiembre de 2022 de la cual se obtuvo 1 Informe de Hallazgos y 1 Informe Complementario (no notificados a la Universidad) y 1 realizada en noviembre de 2025, en la cual se realizaron entrevistas y se solicitó información mediante Anexo. Adicionalmente a los hechos que motivaron la supervisión (falta de laboratorios y biblioteca) se identificaron en 2025, aspectos relacionados con la falta de gestión de residuos, seguridad del local y mantenimiento. | X2: VÍCTOR DE LA CRUZ | Y2: OS Antecedentes Barzen Manrique (Feb-26) CBC III Víctor de la Cruz (Feb-26) Priorizada para ser cerrada en marzo 2026. La CBC escala a SNP | Z2: Sí | AA2: 46101 | AB2: =IF(AA2<TODAY(),"VENCIDO","POR VENCER") -> VENCIDO | AC2: 46108 | AD2: EN PROCESO | AE2: Informe N° 00484-2026-SUNEDU-DS-DIRESESU-UVE que recomendó: El archivamiento de la AD-005-2022 en lo referido a la verificación del mantenimiento de las CBC V y VI del Modelo de Licenciamiento, vinculadas a la existencia mínima del 25% de docentes a tiempo completo del total, así como a los procesos de selección, evaluación y capacitación docente, y a la disponibilidad del acervo bibliográfico. 2) Inicio de una supervisión no programada respecto de la CBC III | AF2: {=IFERROR(_xlfn.XLOOKUP(TRIM($E2),TRIM('Año 2026'!$E$3:$E$66),'Año 2026'!$G$3:$G$66),"")} | AG2: {=IFERROR(_xlfn.XLOOKUP(TRIM($E2),TRIM('Año 2026'!$E$3:$E$66),'Año 2026'!$H$3:$H$66),"")} | AH2: {=IFERROR(_xlfn.XLOOKUP(TRIM($E2),TRIM('Año 2026'!$E$3:$E$66),'Año 2026'!$I$3:$I$66),"")} | AI2: {=IFERROR(_xlfn.XLOOKUP(TRIM($E2),TRIM('Año 2026'!$E$3:$E$66),'Año 2026'!$J$3:$J$66),"")} | AJ2: {=IFERROR(_xlfn.XLOOKUP(TRIM($E2),TRIM('Año 2026'!$E$3:$E$66),'Año 2026'!$K$3:$K$66),"")} | AK2: {=IFERROR(_xlfn.XLOOKUP(TRIM($E2),TRIM('Año 2026'!$E$3:$E$66),'Año 2026'!$L$3:$L$66),"")} | AL2: {=IFERROR(_xlfn.XLOOKUP(TRIM($E2),TRIM('Año 2026'!$E$3:$E$66),'Año 2026'!$M$3:$M$66),"")} | AM2: {=IFERROR(_xlfn.XLOOKUP(TRIM($E2),TRIM('Año 2026'!$E$3:$E$66),'Año 2026'!$N$3:$N$66),"")} | AN2: {=IFERROR(_xlfn.XLOOKUP(TRIM($E2),TRIM('Año 2026'!$E$3:$E$66),'Año 2026'!$O$3:$O$66),"")} | AO2: {=IFERROR(_xlfn.XLOOKUP(TRIM($E2),TRIM('Año 2026'!$E$3:$E$66),'Año 2026'!$P$3:$P$66),"")} | AP2: {=IFERROR(_xlfn.XLOOKUP(TRIM($E2),TRIM('Año 2026'!$E$3:$E$66),'Año 2026'!$Q$3:$Q$66),"")} | AQ2: {=IFERROR(_xlfn.XLOOKUP(TRIM($E2),TRIM('Año 2026'!$E$3:$E$66),'Año 2026'!$R$3:$R$66),"")} | AR2: {=IFERROR(_xlfn.XLOOKUP(TRIM($E2),TRIM('Año 2026'!$E$3:$E$66),'Año 2026'!$S$3:$S$66),"")} | AS2: {=IFERROR(_xlfn.XLOOKUP(TRIM($E2),TRIM('Año 2026'!$E$3:$E$66),'Año 2026'!$T$3:$T$66),"")} | AT2: {=IFERROR(_xlfn.XLOOKUP(TRIM($E2),TRIM('Año 2026'!$E$3:$E$66),'Año 2026'!$U$3:$U$66),"")} | AU2: {=IFERROR(_xlfn.XLOOKUP(TRIM($E2),TRIM('Año 2026'!$E$3:$E$66),'Año 2026'!$V$3:$V$66),"")} | AV2: {=IFERROR(_xlfn.XLOOKUP(TRIM($E2),TRIM('Año 2026'!$E$3:$E$66),'Año 2026'!$W$3:$W$66),"")} | AW2: {=IFERROR(_xlfn.XLOOKUP(TRIM($E2),TRIM('Año 2026'!$E$3:$E$66),'Año 2026'!$X$3:$X$66),"")} | AX2: {=IFERROR(_xlfn.XLOOKUP(TRIM($E2),TRIM('Año 2026'!$E$3:$E$66),'Año 2026'!$Y$3:$Y$66),"")} | AY2: {=IFERROR(_xlfn.XLOOKUP(TRIM($E2),TRIM('Año 2026'!$E$3:$E$66),'Año 2026'!$Z$3:$Z$66),"")} | AZ2: {=IFERROR(_xlfn.XLOOKUP(TRIM($E2),TRIM('Año 2026'!$E$3:$E$66),'Año 2026'!$AA$3:$AA$66),"")} | BA2: {=IFERROR(_xlfn.XLOOKUP(TRIM($E2),TRIM('Año 2026'!$E$3:$E$66),'Año 2026'!$AB$3:$AB$66),"")} | BB2: {=IFERROR(_xlfn.XLOOKUP(TRIM($E2),TRIM('Año 2026'!$E$3:$E$66),'Año 2026'!$AC$3:$AC$66),"")} | BC2: {=IFERROR(_xlfn.XLOOKUP(TRIM($E2),TRIM('Año 2026'!$E$3:$E$66),'Año 2026'!$AD$3:$AD$66),"")}
A3: 2 | B3: 2022 | C3: SNP | D3: Correo electrónico | E3: 01028-2022-SUNEDU/02-13 | F3: Atendido | H3: 28 | I3: Pública | J3: SL03 | K3: Huancavelica | L3: Tayacaja | M3: Ahuaycha | N3: Av. Universitaria Mz. A Lt. 12, 13 y 14 | O3: MLI | P3: III, VI | Q3: 17, 19, 20, 21, 22, 23, 24, 27, 29, 30, 44 | R3: Denuncia presentada por estudiantes de la Universidad Nacional Autónoma de Tayacaja, mediante la cual se solicita la intervención de la SUNEDU y la reorganización de los miembros de la Comisión Organizadora, debido a presuntas deficiencias institucionales consistentes en la falta de infraestructura y de pabellones y laboratorios para el desarrollo de los programas académicos, la ausencia de rendición de cuentas del presupuesto anual universitario, la falta de construcción e implementación de la sede administrativa, deficiencias en el servicio y/o contrato del proveedor del comedor universitario, la inexistencia del servicio de internet, deficiencias en el reglamento académico y el no reconocimiento de las juntas estudiantiles de las cinco carreras. | S3: ALTA | T3: 1 | U3: La Universidad remitió información requerida en el Acta de Supervisión, mediante Oficio N° 557 - 2025- UNAT del 21.11.25 | V3: 45982 | W3: El expediente estuvo asignado a Carla, pendiente consultar si se realizó alguna acción. Pendiente inicio de elaboración de IR. | X3: CARLA LA TORRE | Y3: OS Antecedentes: Barzen Manrique (Mar-26) Priorizada para ser cerrada en marzo 2026. CBC III Carla La Torre IR del 23.02.26 al 20.03.26 Priorizada para ser cerrada en marzo 2026. | Z3: Sí | AA3: 46141 | AB3: =IF(AA3<TODAY(),"VENCIDO","POR VENCER") -> VENCIDO | AC3: 46108 | AD3: COMPLETADO | AE3: Informe de Resultados N° 00109-2026-SUNEDU-DS-DIRESESU-UVE que recomienda la derivación a UDRA. | AF3: {=IFERROR(_xlfn.XLOOKUP(TRIM($E3),TRIM('Año 2026'!$E$3:$E$66),'Año 2026'!$G$3:$G$66),"")} | AG3: {=IFERROR(_xlfn.XLOOKUP(TRIM($E3),TRIM('Año 2026'!$E$3:$E$66),'Año 2026'!$H$3:$H$66),"")} | AH3: {=IFERROR(_xlfn.XLOOKUP(TRIM($E3),TRIM('Año 2026'!$E$3:$E$66),'Año 2026'!$I$3:$I$66),"")} | AI3: {=IFERROR(_xlfn.XLOOKUP(TRIM($E3),TRIM('Año 2026'!$E$3:$E$66),'Año 2026'!$J$3:$J$66),"")} | AJ3: {=IFERROR(_xlfn.XLOOKUP(TRIM($E3),TRIM('Año 2026'!$E$3:$E$66),'Año 2026'!$K$3:$K$66),"")} | AK3: {=IFERROR(_xlfn.XLOOKUP(TRIM($E3),TRIM('Año 2026'!$E$3:$E$66),'Año 2026'!$L$3:$L$66),"")} | AL3: {=IFERROR(_xlfn.XLOOKUP(TRIM($E3),TRIM('Año 2026'!$E$3:$E$66),'Año 2026'!$M$3:$M$66),"")} | AM3: {=IFERROR(_xlfn.XLOOKUP(TRIM($E3),TRIM('Año 2026'!$E$3:$E$66),'Año 2026'!$N$3:$N$66),"")} | AN3: {=IFERROR(_xlfn.XLOOKUP(TRIM($E3),TRIM('Año 2026'!$E$3:$E$66),'Año 2026'!$O$3:$O$66),"")} | AO3: {=IFERROR(_xlfn.XLOOKUP(TRIM($E3),TRIM('Año 2026'!$E$3:$E$66),'Año 2026'!$P$3:$P$66),"")} | AP3: {=IFERROR(_xlfn.XLOOKUP(TRIM($E3),TRIM('Año 2026'!$E$3:$E$66),'Año 2026'!$Q$3:$Q$66),"")} | AQ3: {=IFERROR(_xlfn.XLOOKUP(TRIM($E3),TRIM('Año 2026'!$E$3:$E$66),'Año 2026'!$R$3:$R$66),"")} | AR3: {=IFERROR(_xlfn.XLOOKUP(TRIM($E3),TRIM('Año 2026'!$E$3:$E$66),'Año 2026'!$S$3:$S$66),"")} | AS3: {=IFERROR(_xlfn.XLOOKUP(TRIM($E3),TRIM('Año 2026'!$E$3:$E$66),'Año 2026'!$T$3:$T$66),"")} | AT3: {=IFERROR(_xlfn.XLOOKUP(TRIM($E3),TRIM('Año 2026'!$E$3:$E$66),'Año 2026'!$U$3:$U$66),"")} | AU3: {=IFERROR(_xlfn.XLOOKUP(TRIM($E3),TRIM('Año 2026'!$E$3:$E$66),'Año 2026'!$V$3:$V$66),"")} | AV3: {=IFERROR(_xlfn.XLOOKUP(TRIM($E3),TRIM('Año 2026'!$E$3:$E$66),'Año 2026'!$W$3:$W$66),"")} | AW3: {=IFERROR(_xlfn.XLOOKUP(TRIM($E3),TRIM('Año 2026'!$E$3:$E$66),'Año 2026'!$X$3:$X$66),"")} | AX3: {=IFERROR(_xlfn.XLOOKUP(TRIM($E3),TRIM('Año 2026'!$E$3:$E$66),'Año 2026'!$Y$3:$Y$66),"")} | AY3: {=IFERROR(_xlfn.XLOOKUP(TRIM($E3),TRIM('Año 2026'!$E$3:$E$66),'Año 2026'!$Z$3:$Z$66),"")} | AZ3: {=IFERROR(_xlfn.XLOOKUP(TRIM($E3),TRIM('Año 2026'!$E$3:$E$66),'Año 2026'!$AA$3:$AA$66),"")} | BA3: {=IFERROR(_xlfn.XLOOKUP(TRIM($E3),TRIM('Año 2026'!$E$3:$E$66),'Año 2026'!$AB$3:$AB$66),"")} | BB3: {=IFERROR(_xlfn.XLOOKUP(TRIM($E3),TRIM('Año 2026'!$E$3:$E$66),'Año 2026'!$AC$3:$AC$66),"")} | BC3: {=IFERROR(_xlfn.XLOOKUP(TRIM($E3),TRIM('Año 2026'!$E$3:$E$66),'Año 2026'!$AD$3:$AD$66),"")}
A4: 3 | B4: 2022 | C4: SNP | D4: No programada - oficio | E4: 02730-2022-SUNEDU/02-13 | F4: Atendido | H4: 25 | I4: Privada | J4: SL01, SL03, SL10, SL14, F06L02 | K4: SL01,SL03,SL10,SL14: Lima | F06L02: La Libertad | L4: SL01,SL03,SL10,SL14: Lima | F06L02: Trujillo | M4: SL01,SL03,SL10,SL14: Lima | F06L02: Trujillo | N4: SL01: Av. Abel Bergasse Du Petit Thouars 114 y 116 Urb. Santa Beatriz | SL03: Av. Petit Thouars Mz. 3B Lt. 9 urbanización Fundo Santa Beatriz Cercado | SL10: Jirón Hernán Velarde N° 143, N° 149, N° 151 y N° 153; frente al Parque Hernán Velarde N° 33 y N° 35 | SL14: Jirón Manuel Nicolás Corpancho N° 358-360 Cercado | F06L02: Av. Nicolás de Piérola (antes Carretera Panamericana Norte) 1221- 1223-1225-1227- 1229-1231- 1235 | O4: MLI | P4: III | Q4: 17, 20, 27, 28, 30 | R4: Caso referido a presuntas afectaciones en locales licenciados de la Universidad Tecnológica del Perú (SL01, SL03, SL10, SL14 y F06L02), derivadas del traslado (Trujillo) y, en algunos casos (Lima), fusión de laboratorios y talleres entre sedes. La supervisión preliminar identificó la reubicación de ambientes de enseñanza en sótanos y zonas colindantes a estacionamientos, lo que podría comprometer las condiciones de habitabilidad (confort acústico y térmico), seguridad (ausencia de circulación peatonal diferenciada y medios de evacuación, así como falta de actualización de la identificación de riesgos), y la disponibilidad de equipamiento mínimo, al evidenciarse una reducción en la cantidad de equipos respecto a lo declarado en el licenciamiento. | S4: MEDIA | T4: 1 | U4: Respuesta por parte de la Universidad a los requerimientos realizados por la DISUP en el Informe preliminar N° 047-2022-SUNEDU/02-13, del 20.02.23 | V4: 44977 | W4: Está pendiente la elaboración del Informe de Resultados con la última información remitida por la Universidad. | X4: ANTHONY SAAVEDRA | Y4: Pendiente de revisión por Gigi Desde el 09.02.26 al 20.02.26 Priorizada para ser cerrada en febrero 2026 | Z4: Sí | AA4: 46101 | AB4: =IF(AA4<TODAY(),"VENCIDO","POR VENCER") -> VENCIDO | AC4: 46108 | AD4: COMPLETADO | AE4: INFORME DE RESULTADOS N° 00065-2026-SUNEDU-DS-DIRESESU-UVE | AF4: {=IFERROR(_xlfn.XLOOKUP(TRIM($E4),TRIM('Año 2026'!$E$3:$E$66),'Año 2026'!$G$3:$G$66),"")} | AG4: {=IFERROR(_xlfn.XLOOKUP(TRIM($E4),TRIM('Año 2026'!$E$3:$E$66),'Año 2026'!$H$3:$H$66),"")} | AH4: {=IFERROR(_xlfn.XLOOKUP(TRIM($E4),TRIM('Año 2026'!$E$3:$E$66),'Año 2026'!$I$3:$I$66),"")} | AI4: {=IFERROR(_xlfn.XLOOKUP(TRIM($E4),TRIM('Año 2026'!$E$3:$E$66),'Año 2026'!$J$3:$J$66),"")} | AJ4: {=IFERROR(_xlfn.XLOOKUP(TRIM($E4),TRIM('Año 2026'!$E$3:$E$66),'Año 2026'!$K$3:$K$66),"")} | AK4: {=IFERROR(_xlfn.XLOOKUP(TRIM($E4),TRIM('Año 2026'!$E$3:$E$66),'Año 2026'!$L$3:$L$66),"")} | AL4: {=IFERROR(_xlfn.XLOOKUP(TRIM($E4),TRIM('Año 2026'!$E$3:$E$66),'Año 2026'!$M$3:$M$66),"")} | AM4: {=IFERROR(_xlfn.XLOOKUP(TRIM($E4),TRIM('Año 2026'!$E$3:$E$66),'Año 2026'!$N$3:$N$66),"")} | AN4: {=IFERROR(_xlfn.XLOOKUP(TRIM($E4),TRIM('Año 2026'!$E$3:$E$66),'Año 2026'!$O$3:$O$66),"")} | AO4: {=IFERROR(_xlfn.XLOOKUP(TRIM($E4),TRIM('Año 2026'!$E$3:$E$66),'Año 2026'!$P$3:$P$66),"")} | AP4: {=IFERROR(_xlfn.XLOOKUP(TRIM($E4),TRIM('Año 2026'!$E$3:$E$66),'Año 2026'!$Q$3:$Q$66),"")} | AQ4: {=IFERROR(_xlfn.XLOOKUP(TRIM($E4),TRIM('Año 2026'!$E$3:$E$66),'Año 2026'!$R$3:$R$66),"")} | AR4: {=IFERROR(_xlfn.XLOOKUP(TRIM($E4),TRIM('Año 2026'!$E$3:$E$66),'Año 2026'!$S$3:$S$66),"")} | AS4: {=IFERROR(_xlfn.XLOOKUP(TRIM($E4),TRIM('Año 2026'!$E$3:$E$66),'Año 2026'!$T$3:$T$66),"")} | AT4: {=IFERROR(_xlfn.XLOOKUP(TRIM($E4),TRIM('Año 2026'!$E$3:$E$66),'Año 2026'!$U$3:$U$66),"")} | AU4: {=IFERROR(_xlfn.XLOOKUP(TRIM($E4),TRIM('Año 2026'!$E$3:$E$66),'Año 2026'!$V$3:$V$66),"")} | AV4: {=IFERROR(_xlfn.XLOOKUP(TRIM($E4),TRIM('Año 2026'!$E$3:$E$66),'Año 2026'!$W$3:$W$66),"")} | AW4: {=IFERROR(_xlfn.XLOOKUP(TRIM($E4),TRIM('Año 2026'!$E$3:$E$66),'Año 2026'!$X$3:$X$66),"")} | AX4: {=IFERROR(_xlfn.XLOOKUP(TRIM($E4),TRIM('Año 2026'!$E$3:$E$66),'Año 2026'!$Y$3:$Y$66),"")} | AY4: {=IFERROR(_xlfn.XLOOKUP(TRIM($E4),TRIM('Año 2026'!$E$3:$E$66),'Año 2026'!$Z$3:$Z$66),"")} | AZ4: {=IFERROR(_xlfn.XLOOKUP(TRIM($E4),TRIM('Año 2026'!$E$3:$E$66),'Año 2026'!$AA$3:$AA$66),"")} | BA4: {=IFERROR(_xlfn.XLOOKUP(TRIM($E4),TRIM('Año 2026'!$E$3:$E$66),'Año 2026'!$AB$3:$AB$66),"")} | BB4: {=IFERROR(_xlfn.XLOOKUP(TRIM($E4),TRIM('Año 2026'!$E$3:$E$66),'Año 2026'!$AC$3:$AC$66),"")} | BC4: {=IFERROR(_xlfn.XLOOKUP(TRIM($E4),TRIM('Año 2026'!$E$3:$E$66),'Año 2026'!$AD$3:$AD$66),"")}
A5: 4 | B5: 2024 | C5: Denuncia | D5: Correo electrónico | E5: 02438-2024-SUNEDU/02-13 | F5: En trámite | G5: 2024INT0000014220-SUNEDU | H5: 42 | I5: Privada | J5: SL01 | K5: Lima | L5: Lima | M5: La Molina | N5: Av. La Molina N° 3755, Sol de la Molina, distrito de La Molina, provincia y departamento de Lima. | O5: MLI | P5: III, V | Q5: 27 | R5: Hace de conocimiento lo siguiente: (I) La universidad vendría adicionando carreras y admitiría más alumnos, sin contar con los docentes necesarios para el dictado de clases. (II) Se les obligaría a pagar por un seguro que no lo necesitarían.III) El aforo de las aulas estaría excediendo el límite permitido. La Universidad mediante Oficio N° 045-2025-SG-UCAL del 16 de julio de 2025, presentó los ocho (8) puntos de la condicion III y de la condicion VI la contratación del seguro que ofrece UCAL no es obligatoria, el estudiante puede optar por adquirir la póliza que más le convenga.exigencia de pagar por un seguro Jenny proyectó el Oficio de Requirimiento Complementario, pendiente de revisión y envío a la universidad. | S5: MEDIA | T5: 2 | U5: Informacion solicitada mediante Oficio Nº 02404-2025-SUNEDU-DS-DIRESESU-UVE del 01 de Julio de 2025, se solicita ocho (8) puntos de la Condición III (indicadores 27 y 28) del Modelo de Licenciamiento y Condición V (indicadores 39 y 40) del Modelo de Licenciamiento y Condición II (indicador 6) del Modelo para programas semipresenciales y a distancia | V5: 45841 | W5: La Universidad presentó el Oficio N° 045-2025-SG-UCAL del 16.07.2025, respondiendo al Oficio N° 02404-2025-SUNEDU-DS-DIRESESU-UVE con el cual se solicita información acerca de la denuncia. Pendiente de analizar infromación presentada y elaborar IR. | Y5: Pendiente proyectar requerimiento de información de CBC III y V Antecedentes Barzen Manrique CBC III Carla La Torre 01.07.26 al 17.07.26 CBC V pendiente definir evaluador Priorizada para ser cerrada en julio 2026. | Z5: Sí | AA5: 46227 | AB5: =IF(AA5<TODAY(),"VENCIDO","POR VENCER") -> POR VENCER | AC5: 46234 | AD5: EN PROCESO | AE5: Carta y/o Oficio | AF5: {=IFERROR(_xlfn.XLOOKUP(TRIM($E5),TRIM('Año 2026'!$E$3:$E$66),'Año 2026'!$G$3:$G$66),"")} -> OFICIO Nº 02404-2025-SUNEDU-DS-DIRESESU-UVE | AG5: {=IFERROR(_xlfn.XLOOKUP(TRIM($E5),TRIM('Año 2026'!$E$3:$E$66),'Año 2026'!$H$3:$H$66),"")} -> 0 | AH5: {=IFERROR(_xlfn.XLOOKUP(TRIM($E5),TRIM('Año 2026'!$E$3:$E$66),'Año 2026'!$I$3:$I$66),"")} -> 0 | AI5: {=IFERROR(_xlfn.XLOOKUP(TRIM($E5),TRIM('Año 2026'!$E$3:$E$66),'Año 2026'!$J$3:$J$66),"")} -> 0 | AJ5: {=IFERROR(_xlfn.XLOOKUP(TRIM($E5),TRIM('Año 2026'!$E$3:$E$66),'Año 2026'!$K$3:$K$66),"")} -> 0 | AK5: {=IFERROR(_xlfn.XLOOKUP(TRIM($E5),TRIM('Año 2026'!$E$3:$E$66),'Año 2026'!$L$3:$L$66),"")} -> 0 | AL5: {=IFERROR(_xlfn.XLOOKUP(TRIM($E5),TRIM('Año 2026'!$E$3:$E$66),'Año 2026'!$M$3:$M$66),"")} -> 0 | AM5: {=IFERROR(_xlfn.XLOOKUP(TRIM($E5),TRIM('Año 2026'!$E$3:$E$66),'Año 2026'!$N$3:$N$66),"")} -> 0 | AN5: {=IFERROR(_xlfn.XLOOKUP(TRIM($E5),TRIM('Año 2026'!$E$3:$E$66),'Año 2026'!$O$3:$O$66),"")} -> 0 | AO5: {=IFERROR(_xlfn.XLOOKUP(TRIM($E5),TRIM('Año 2026'!$E$3:$E$66),'Año 2026'!$P$3:$P$66),"")} -> 0 | AP5: {=IFERROR(_xlfn.XLOOKUP(TRIM($E5),TRIM('Año 2026'!$E$3:$E$66),'Año 2026'!$Q$3:$Q$66),"")} -> 0 | AQ5: {=IFERROR(_xlfn.XLOOKUP(TRIM($E5),TRIM('Año 2026'!$E$3:$E$66),'Año 2026'!$R$3:$R$66),"")} -> 0 | AR5: {=IFERROR(_xlfn.XLOOKUP(TRIM($E5),TRIM('Año 2026'!$E$3:$E$66),'Año 2026'!$S$3:$S$66),"")} -> 0 | AS5: {=IFERROR(_xlfn.XLOOKUP(TRIM($E5),TRIM('Año 2026'!$E$3:$E$66),'Año 2026'!$T$3:$T$66),"")} -> 0 | AT5: {=IFERROR(_xlfn.XLOOKUP(TRIM($E5),TRIM('Año 2026'!$E$3:$E$66),'Año 2026'!$U$3:$U$66),"")} -> 0 | AU5: {=IFERROR(_xlfn.XLOOKUP(TRIM($E5),TRIM('Año 2026'!$E$3:$E$66),'Año 2026'!$V$3:$V$66),"")} -> 0 | AV5: {=IFERROR(_xlfn.XLOOKUP(TRIM($E5),TRIM('Año 2026'!$E$3:$E$66),'Año 2026'!$W$3:$W$66),"")} -> 0 | AW5: {=IFERROR(_xlfn.XLOOKUP(TRIM($E5),TRIM('Año 2026'!$E$3:$E$66),'Año 2026'!$X$3:$X$66),"")} -> 0 | AX5: {=IFERROR(_xlfn.XLOOKUP(TRIM($E5),TRIM('Año 2026'!$E$3:$E$66),'Año 2026'!$Y$3:$Y$66),"")} -> 0 | AY5: {=IFERROR(_xlfn.XLOOKUP(TRIM($E5),TRIM('Año 2026'!$E$3:$E$66),'Año 2026'!$Z$3:$Z$66),"")} -> 0 | AZ5: {=IFERROR(_xlfn.XLOOKUP(TRIM($E5),TRIM('Año 2026'!$E$3:$E$66),'Año 2026'!$AA$3:$AA$66),"")} -> 0 | BA5: {=IFERROR(_xlfn.XLOOKUP(TRIM($E5),TRIM('Año 2026'!$E$3:$E$66),'Año 2026'!$AB$3:$AB$66),"")} -> 0 | BB5: {=IFERROR(_xlfn.XLOOKUP(TRIM($E5),TRIM('Año 2026'!$E$3:$E$66),'Año 2026'!$AC$3:$AC$66),"")} -> 0 | BC5: {=IFERROR(_xlfn.XLOOKUP(TRIM($E5),TRIM('Año 2026'!$E$3:$E$66),'Año 2026'!$AD$3:$AD$66),"")} -> 0
A6: 5 | B6: 2023 | C6: SNP | D6: Web | E6: 01709-2023-SUNEDU/02-13 | F6: En trámite | G6: 031172-2023-SUNEDU-TD, 2024INT0000006179-SUNEDU | H6: 31 | I6: Pública | J6: SL01, SL05, F01L01, F02L01, F03L01 | K6: Pasco | L6: Pasco | M6: Yanacancha | N6: 1.-SL01, cuya ubicación es Programa de Vivienda Urbanización San Juan Pampa Mz Q Lote 1 Sector Centro Comercial, distrito de Yanacancha, provincia de Pasco, departamento de Pasco. Contiene, entre otras, las facultades de Medicina Humana, Ingeniería de Minas, Ciencias de la Comunicación, Odontología, e Ingeniería. | - SL05, cuya ubicación es Terreno ubicado en Pucayacu, distrito de Yanacancha, provincia de Pasco, departamento de Pasco. Contiene la facultad de Medicina Humana e Ingeniería de Minas | 2.-FILIALES: | F01L01, cuya ubicación es Valle Oxapampa, Sector Miraflores S/N, distrito de Oxapampa, provincia de Oxapampa, departamento de Pasco. Contiene, entre otras, la facultad de Ingeniería. | F03L01, cuya ubicación es Av. Circunvalación Mz 0206 Lt. S/N, Urbanización Pampa del Carmen, distrito de Chanchamayo, provincia de Chanchamayo, departamento de Junín. Contiene, entre otras, la facultad de Ciencias de la Comunicación. | O6: MLI | P6: III, VI | Q6: 19 | R6: Denuncia contra la Universidad Nacional Daniel Alcides Carrión (UNDAC) por presuntas irregularidades que afectarían el mantenimiento de las Condiciones Básicas de Calidad, referidas a: i) paralización de la obra de remodelación de instalaciones eléctricas en la sede central San Juan (Yanacancha), generando riesgos para la seguridad de los estudiantes por zanjas abiertas y cables expuestos (Denuncia 1: RTD 031167-2023-SUNEDU-TD, del 30/06/2023); ii) falta de prestación del servicio de comedor universitario en las filiales de Oxapampa (F01L01), Tarma (F02L01) y Chanchamayo (F03L01) (Denuncia 2: RTD 031172-2023-SUNEDU-TD, del 30/06/2023) | S6: MEDIA | T6: 2 | U6: Se escala, de denunacia a SNP, pendiente de firma de ejecutiva Mediante Oficio N° 000281-2025-UNDAC/R, remitio informacion peticionaria: 1. Informe N°000037-2025-DBU 2.Informe Tecnico N°000024-2025-UEI * Solo se hizo un cotejo de información falta evaluarla | V6: 45797 | W6: A sido trasladado a otro expediente: 4. AD-003-2024 (UNDAC), ya cuenta con Visita de Inspección, la Universidad ha entregado información(además se deberá acumular lo del expediente En la visita de inspección de octubre de 2025, no se solicitó información vinculada a esta denuncia. En cuanto firmen el oficio se eleva a SNP. | Y6: OS Antecedentes Barzen Manrique CBC III Jenny Mendez (Mar-26) CBC VI Ysella Arguedas (Mar-26) Priorizada para ser cerrada en marzo 2026 Para elaboración de IR con información post VI y lo que entregará del exp 01927-2025-SUNEDI/02-13) Priorizada para ser cerrada en abril 2026 | Z6: Sí | AA6: 46129 | AB6: =IF(AA6<TODAY(),"VENCIDO","POR VENCER") -> VENCIDO | AC6: 46136 | AD6: EN PROCESO | AE6: Informe de Resultados | AF6: {=IFERROR(_xlfn.XLOOKUP(TRIM($E6),TRIM('Año 2026'!$E$3:$E$66),'Año 2026'!$G$3:$G$66),"")} | AG6: {=IFERROR(_xlfn.XLOOKUP(TRIM($E6),TRIM('Año 2026'!$E$3:$E$66),'Año 2026'!$H$3:$H$66),"")} | AH6: {=IFERROR(_xlfn.XLOOKUP(TRIM($E6),TRIM('Año 2026'!$E$3:$E$66),'Año 2026'!$I$3:$I$66),"")} | AI6: {=IFERROR(_xlfn.XLOOKUP(TRIM($E6),TRIM('Año 2026'!$E$3:$E$66),'Año 2026'!$J$3:$J$66),"")} | AJ6: {=IFERROR(_xlfn.XLOOKUP(TRIM($E6),TRIM('Año 2026'!$E$3:$E$66),'Año 2026'!$K$3:$K$66),"")} | AK6: {=IFERROR(_xlfn.XLOOKUP(TRIM($E6),TRIM('Año 2026'!$E$3:$E$66),'Año 2026'!$L$3:$L$66),"")} | AL6: {=IFERROR(_xlfn.XLOOKUP(TRIM($E6),TRIM('Año 2026'!$E$3:$E$66),'Año 2026'!$M$3:$M$66),"")} | AM6: {=IFERROR(_xlfn.XLOOKUP(TRIM($E6),TRIM('Año 2026'!$E$3:$E$66),'Año 2026'!$N$3:$N$66),"")} | AN6: {=IFERROR(_xlfn.XLOOKUP(TRIM($E6),TRIM('Año 2026'!$E$3:$E$66),'Año 2026'!$O$3:$O$66),"")} | AO6: {=IFERROR(_xlfn.XLOOKUP(TRIM($E6),TRIM('Año 2026'!$E$3:$E$66),'Año 2026'!$P$3:$P$66),"")} | AP6: {=IFERROR(_xlfn.XLOOKUP(TRIM($E6),TRIM('Año 2026'!$E$3:$E$66),'Año 2026'!$Q$3:$Q$66),"")} | AQ6: {=IFERROR(_xlfn.XLOOKUP(TRIM($E6),TRIM('Año 2026'!$E$3:$E$66),'Año 2026'!$R$3:$R$66),"")} | AR6: {=IFERROR(_xlfn.XLOOKUP(TRIM($E6),TRIM('Año 2026'!$E$3:$E$66),'Año 2026'!$S$3:$S$66),"")} | AS6: {=IFERROR(_xlfn.XLOOKUP(TRIM($E6),TRIM('Año 2026'!$E$3:$E$66),'Año 2026'!$T$3:$T$66),"")} | AT6: {=IFERROR(_xlfn.XLOOKUP(TRIM($E6),TRIM('Año 2026'!$E$3:$E$66),'Año 2026'!$U$3:$U$66),"")} | AU6: {=IFERROR(_xlfn.XLOOKUP(TRIM($E6),TRIM('Año 2026'!$E$3:$E$66),'Año 2026'!$V$3:$V$66),"")} | AV6: {=IFERROR(_xlfn.XLOOKUP(TRIM($E6),TRIM('Año 2026'!$E$3:$E$66),'Año 2026'!$W$3:$W$66),"")} | AW6: {=IFERROR(_xlfn.XLOOKUP(TRIM($E6),TRIM('Año 2026'!$E$3:$E$66),'Año 2026'!$X$3:$X$66),"")} | AX6: {=IFERROR(_xlfn.XLOOKUP(TRIM($E6),TRIM('Año 2026'!$E$3:$E$66),'Año 2026'!$Y$3:$Y$66),"")} | AY6: {=IFERROR(_xlfn.XLOOKUP(TRIM($E6),TRIM('Año 2026'!$E$3:$E$66),'Año 2026'!$Z$3:$Z$66),"")} | AZ6: {=IFERROR(_xlfn.XLOOKUP(TRIM($E6),TRIM('Año 2026'!$E$3:$E$66),'Año 2026'!$AA$3:$AA$66),"")} | BA6: {=IFERROR(_xlfn.XLOOKUP(TRIM($E6),TRIM('Año 2026'!$E$3:$E$66),'Año 2026'!$AB$3:$AB$66),"")} | BB6: {=IFERROR(_xlfn.XLOOKUP(TRIM($E6),TRIM('Año 2026'!$E$3:$E$66),'Año 2026'!$AC$3:$AC$66),"")} | BC6: {=IFERROR(_xlfn.XLOOKUP(TRIM($E6),TRIM('Año 2026'!$E$3:$E$66),'Año 2026'!$AD$3:$AD$66),"")}
A7: 6 | B7: 2023 | C7: Accion Directa | D7: Correo electrónico | E7: AD-013-2023 | F7: Atendido | H7: 17 | I7: Pública | J7: SL01 | K7: Lima | L7: Lima | M7: Lurigancho | N7: Avenida Enrique Guzmán y Valle N° 951 | O7: MLI | P7: III, VI | Q7: 19, 30, 44 | R7: La acción directa se motiva tras la comunicación realizada por la propia universidad (RTD N° 15698-2023-SUNEDU-TD, u Oficios N° 0103-2023-R-UNE del 24/03/2023 y Nº 0149-2023-R-UNE del 11/05/2023) señalando que las circunsancias ambientales de su entorno habrían generado afectación a la prestación del servicio educativo de manera presencial: - Destrucción de los canales de agua y pistas; el enlodamiento de las vIas de acceso a las aulas, ambientes académicos y administrativos; y la filtración de agua a los ambientes de clases y comedor universitario. - Los sistemas de abastecimiento de agua no tendrían capacidad para atender a la comunidad universitaria en un contexto de presencialidad. | S7: BAJA | T7: 1 | U7: Visita de inspección realizada en set2025, al respecto la Universidad presentó información y se cuenta con 1 IR elaborado pendiente de revisión final. | V7: 45911 | W7: En la comunicación inicial de la Universidad, que origina la acción de oficio, presentó el "Plan de Contingencia del Proceso de Formación profesional y eduación contínua 2023" mediante el cual planifica acciones que acompañarían su pedido de "flexibilidad para la prestación del servicio educativo en manera virtual para el semestre 2023-I". Disup tuvo reuniones y realizó seguimiento, siendo que en julio de 2023 solicitó información de las acciones que la Universidad ejecutaría frente a los problemas de techos e infraestructura afectada por lluvias. Cuenta con 2 supervisiones de campo, 1 realizada en noviembre de 2023, en la cual señaló que realizó proyectos IOARR´s para la mejora de techos y atender acciones de emergencia de mantenimiento; y 1 segunda visita de inspección realizada el 10 y 11 de setiembre de 2025. | Y7: CULMINADO Informe de Cierre. Recomendación con derivación da DIGESU | Z7: Sí | AA7: 46101 | AB7: =IF(AA7<TODAY(),"VENCIDO","POR VENCER") -> VENCIDO | AC7: 46108 | AD7: COMPLETADO | AE7: INFORME N° 00210-2026-SUNEDU-DS-DIRESESU-UVE | AF7: {=IFERROR(_xlfn.XLOOKUP(TRIM($E7),TRIM('Año 2026'!$E$3:$E$66),'Año 2026'!$G$3:$G$66),"")} | AG7: {=IFERROR(_xlfn.XLOOKUP(TRIM($E7),TRIM('Año 2026'!$E$3:$E$66),'Año 2026'!$H$3:$H$66),"")} | AH7: {=IFERROR(_xlfn.XLOOKUP(TRIM($E7),TRIM('Año 2026'!$E$3:$E$66),'Año 2026'!$I$3:$I$66),"")} | AI7: {=IFERROR(_xlfn.XLOOKUP(TRIM($E7),TRIM('Año 2026'!$E$3:$E$66),'Año 2026'!$J$3:$J$66),"")} | AJ7: {=IFERROR(_xlfn.XLOOKUP(TRIM($E7),TRIM('Año 2026'!$E$3:$E$66),'Año 2026'!$K$3:$K$66),"")} | AK7: {=IFERROR(_xlfn.XLOOKUP(TRIM($E7),TRIM('Año 2026'!$E$3:$E$66),'Año 2026'!$L$3:$L$66),"")} | AL7: {=IFERROR(_xlfn.XLOOKUP(TRIM($E7),TRIM('Año 2026'!$E$3:$E$66),'Año 2026'!$M$3:$M$66),"")} | AM7: {=IFERROR(_xlfn.XLOOKUP(TRIM($E7),TRIM('Año 2026'!$E$3:$E$66),'Año 2026'!$N$3:$N$66),"")} | AN7: {=IFERROR(_xlfn.XLOOKUP(TRIM($E7),TRIM('Año 2026'!$E$3:$E$66),'Año 2026'!$O$3:$O$66),"")} | AO7: {=IFERROR(_xlfn.XLOOKUP(TRIM($E7),TRIM('Año 2026'!$E$3:$E$66),'Año 2026'!$P$3:$P$66),"")} | AP7: {=IFERROR(_xlfn.XLOOKUP(TRIM($E7),TRIM('Año 2026'!$E$3:$E$66),'Año 2026'!$Q$3:$Q$66),"")} | AQ7: {=IFERROR(_xlfn.XLOOKUP(TRIM($E7),TRIM('Año 2026'!$E$3:$E$66),'Año 2026'!$R$3:$R$66),"")} | AR7: {=IFERROR(_xlfn.XLOOKUP(TRIM($E7),TRIM('Año 2026'!$E$3:$E$66),'Año 2026'!$S$3:$S$66),"")} | AS7: {=IFERROR(_xlfn.XLOOKUP(TRIM($E7),TRIM('Año 2026'!$E$3:$E$66),'Año 2026'!$T$3:$T$66),"")} | AT7: {=IFERROR(_xlfn.XLOOKUP(TRIM($E7),TRIM('Año 2026'!$E$3:$E$66),'Año 2026'!$U$3:$U$66),"")} | AU7: {=IFERROR(_xlfn.XLOOKUP(TRIM($E7),TRIM('Año 2026'!$E$3:$E$66),'Año 2026'!$V$3:$V$66),"")} | AV7: {=IFERROR(_xlfn.XLOOKUP(TRIM($E7),TRIM('Año 2026'!$E$3:$E$66),'Año 2026'!$W$3:$W$66),"")} | AW7: {=IFERROR(_xlfn.XLOOKUP(TRIM($E7),TRIM('Año 2026'!$E$3:$E$66),'Año 2026'!$X$3:$X$66),"")} | AX7: {=IFERROR(_xlfn.XLOOKUP(TRIM($E7),TRIM('Año 2026'!$E$3:$E$66),'Año 2026'!$Y$3:$Y$66),"")} | AY7: {=IFERROR(_xlfn.XLOOKUP(TRIM($E7),TRIM('Año 2026'!$E$3:$E$66),'Año 2026'!$Z$3:$Z$66),"")} | AZ7: {=IFERROR(_xlfn.XLOOKUP(TRIM($E7),TRIM('Año 2026'!$E$3:$E$66),'Año 2026'!$AA$3:$AA$66),"")} | BA7: {=IFERROR(_xlfn.XLOOKUP(TRIM($E7),TRIM('Año 2026'!$E$3:$E$66),'Año 2026'!$AB$3:$AB$66),"")} | BB7: {=IFERROR(_xlfn.XLOOKUP(TRIM($E7),TRIM('Año 2026'!$E$3:$E$66),'Año 2026'!$AC$3:$AC$66),"")} | BC7: {=IFERROR(_xlfn.XLOOKUP(TRIM($E7),TRIM('Año 2026'!$E$3:$E$66),'Año 2026'!$AD$3:$AD$66),"")}
A8: 7 | B8: 2023 | C8: Accion Directa | D8: Correo electrónico | E8: AD-015-2023 | F8: Archivado | H8: 21 | I8: Pública | J8: SL01 | K8: Cusco | L8: La Convencion | M8: Santa Ana | N8: El Arenal S/N | O8: MLI | P8: III, IV, V | Q8: 19, 27, 28, 30, 33, 34, 35, 38, 40, 42, 44 | R8: Las acciones iniciarían con Oficio de abril de 2023 que comunica la "supervisión orientativa" para el seguimiento y cumplimiento de las 20 recomendaciones realizadas mediante el Informe de Resultados N° 0025- 2023-SUNEDU/02-13 del 17 de febrero de 2023, el cual fue producto de una supervisión programada realizada previamente. Dichas recomendaciones están relaciionadas con CBC I (gestión de calidad), CBC IV (investigación), CBC V (docentes), VI (servicios complementarios) y adiconalmente refieren a CBC III (ejecución presupuestal de sus proyectos de inversión y de mantenimiento). | S8: ALTA | T8: 2 | U8: Visita de inspección realizada en oct2025, a la espera del envío de información solicitada a la Universidad. | V8: 45946 | W8: Conforme a la inspección, se identificó ausencia de ambientes y afectación de CBC´s, lo cual requeriría de análisis de las mallas de los programas ofertados y del estado de los proyectos de inversión. A la fecha la Universidad no ha presentado la información solicitada en la VI de octubre de 2025. | Y8: Pendiente enviar primer reiterativo de información IR Antecedentes Barzen Manrique CBC III Carla La Torre 04.05.26 al 22.05.26 CBC IV y V - Liz (Por confirmar fechas) Priorizada para ser cerrada en mayo 2026. | Z8: Sí | AA8: 46164 | AB8: =IF(AA8<TODAY(),"VENCIDO","POR VENCER") -> VENCIDO | AC8: 46171 | AD8: COMPLETADO | AE8: Se archivó porque escaló a una SNP | AF8: {=IFERROR(_xlfn.XLOOKUP(TRIM($E8),TRIM('Año 2026'!$E$3:$E$66),'Año 2026'!$G$3:$G$66),"")} | AG8: {=IFERROR(_xlfn.XLOOKUP(TRIM($E8),TRIM('Año 2026'!$E$3:$E$66),'Año 2026'!$H$3:$H$66),"")} | AH8: {=IFERROR(_xlfn.XLOOKUP(TRIM($E8),TRIM('Año 2026'!$E$3:$E$66),'Año 2026'!$I$3:$I$66),"")} | AI8: {=IFERROR(_xlfn.XLOOKUP(TRIM($E8),TRIM('Año 2026'!$E$3:$E$66),'Año 2026'!$J$3:$J$66),"")} | AJ8: {=IFERROR(_xlfn.XLOOKUP(TRIM($E8),TRIM('Año 2026'!$E$3:$E$66),'Año 2026'!$K$3:$K$66),"")} | AK8: {=IFERROR(_xlfn.XLOOKUP(TRIM($E8),TRIM('Año 2026'!$E$3:$E$66),'Año 2026'!$L$3:$L$66),"")} | AL8: {=IFERROR(_xlfn.XLOOKUP(TRIM($E8),TRIM('Año 2026'!$E$3:$E$66),'Año 2026'!$M$3:$M$66),"")} | AM8: {=IFERROR(_xlfn.XLOOKUP(TRIM($E8),TRIM('Año 2026'!$E$3:$E$66),'Año 2026'!$N$3:$N$66),"")} | AN8: {=IFERROR(_xlfn.XLOOKUP(TRIM($E8),TRIM('Año 2026'!$E$3:$E$66),'Año 2026'!$O$3:$O$66),"")} | AO8: {=IFERROR(_xlfn.XLOOKUP(TRIM($E8),TRIM('Año 2026'!$E$3:$E$66),'Año 2026'!$P$3:$P$66),"")} | AP8: {=IFERROR(_xlfn.XLOOKUP(TRIM($E8),TRIM('Año 2026'!$E$3:$E$66),'Año 2026'!$Q$3:$Q$66),"")} | AQ8: {=IFERROR(_xlfn.XLOOKUP(TRIM($E8),TRIM('Año 2026'!$E$3:$E$66),'Año 2026'!$R$3:$R$66),"")} | AR8: {=IFERROR(_xlfn.XLOOKUP(TRIM($E8),TRIM('Año 2026'!$E$3:$E$66),'Año 2026'!$S$3:$S$66),"")} | AS8: {=IFERROR(_xlfn.XLOOKUP(TRIM($E8),TRIM('Año 2026'!$E$3:$E$66),'Año 2026'!$T$3:$T$66),"")} | AT8: {=IFERROR(_xlfn.XLOOKUP(TRIM($E8),TRIM('Año 2026'!$E$3:$E$66),'Año 2026'!$U$3:$U$66),"")} | AU8: {=IFERROR(_xlfn.XLOOKUP(TRIM($E8),TRIM('Año 2026'!$E$3:$E$66),'Año 2026'!$V$3:$V$66),"")} | AV8: {=IFERROR(_xlfn.XLOOKUP(TRIM($E8),TRIM('Año 2026'!$E$3:$E$66),'Año 2026'!$W$3:$W$66),"")} | AW8: {=IFERROR(_xlfn.XLOOKUP(TRIM($E8),TRIM('Año 2026'!$E$3:$E$66),'Año 2026'!$X$3:$X$66),"")} | AX8: {=IFERROR(_xlfn.XLOOKUP(TRIM($E8),TRIM('Año 2026'!$E$3:$E$66),'Año 2026'!$Y$3:$Y$66),"")} | AY8: {=IFERROR(_xlfn.XLOOKUP(TRIM($E8),TRIM('Año 2026'!$E$3:$E$66),'Año 2026'!$Z$3:$Z$66),"")} | AZ8: {=IFERROR(_xlfn.XLOOKUP(TRIM($E8),TRIM('Año 2026'!$E$3:$E$66),'Año 2026'!$AA$3:$AA$66),"")} | BA8: {=IFERROR(_xlfn.XLOOKUP(TRIM($E8),TRIM('Año 2026'!$E$3:$E$66),'Año 2026'!$AB$3:$AB$66),"")} | BB8: {=IFERROR(_xlfn.XLOOKUP(TRIM($E8),TRIM('Año 2026'!$E$3:$E$66),'Año 2026'!$AC$3:$AC$66),"")} | BC8: {=IFERROR(_xlfn.XLOOKUP(TRIM($E8),TRIM('Año 2026'!$E$3:$E$66),'Año 2026'!$AD$3:$AD$66),"")}
A9: 8 | B9: 2023 | C9: SNP | D9: No programada - oficio | E9: 00222-2023-SUNEDU/02-13 | F9: En trámite | H9: 49 | I9: Pública | J9: F04L01 | K9: Cusco | L9: Espinar | M9: Yauri | N9: Calle 21 de junio, sector Magisterial | O9: MLI | P9: III, V, VI | Q9: 19, 20, 21, 27, 28, 30, 39, 40, 41, 50 | R9: Denuncia trasladada por la congresista Ruth Luque Ibarra, referida a presuntas deficiencias en la infraestructura, equipamiento y condiciones de seguridad de las escuelas profesionales de Medicina Veterinaria y Educación, ubicadas en la filial Espinar (local F04L01) de la Universidad Nacional de San Antonio Abad del Cusco, consistentes en la inexistencia de un ambiente exclusivo para biblioteca y material bibliográfico insuficiente, insuficiencia de docentes para el dictado de clases, carencias en el centro de cómputo, riesgos eléctricos y deficiencias en las instalaciones sanitarias, así como daños en cielos rasos por filtraciones pluviales. Asimismo, se reporta que los establos y galpones (laboratorios) habrían sido construidos de manera inadecuada, generando riesgo de colapso o fallas estructurales. | S9: ALTA | U9: Respuesta por parte de la Universidad a los requerimientos realizados en el Acta de Supervisión, mediante Oficio N° 598-OGC-2025-UNSAAC del 31.12.25 | V9: 46022 | W9: Se realizó visita de inspección y se realizó requerimiento de información, estaría pendiente la revisión remitida por parte de la Universidad y determinar si es necesario un requerimiento complementario o se procede a elaborar el IR. | X9: JENNY MENDEZ | Y9: OS CBC III Jenny Mendez (Feb-26) CBC V y VI Ysella Arguedas (Feb-26) Priorizada para ser cerrada en mayo 2026. | Z9: Sí | AA9: 46129 | AB9: =IF(AA9<TODAY(),"VENCIDO","POR VENCER") -> VENCIDO | AC9: 46136 | AD9: EN PROCESO | AE9: Informe de Resultados | AF9: {=IFERROR(_xlfn.XLOOKUP(TRIM($E9),TRIM('Año 2026'!$E$3:$E$66),'Año 2026'!$G$3:$G$66),"")} | AG9: {=IFERROR(_xlfn.XLOOKUP(TRIM($E9),TRIM('Año 2026'!$E$3:$E$66),'Año 2026'!$H$3:$H$66),"")} | AH9: {=IFERROR(_xlfn.XLOOKUP(TRIM($E9),TRIM('Año 2026'!$E$3:$E$66),'Año 2026'!$I$3:$I$66),"")} | AI9: {=IFERROR(_xlfn.XLOOKUP(TRIM($E9),TRIM('Año 2026'!$E$3:$E$66),'Año 2026'!$J$3:$J$66),"")} | AJ9: {=IFERROR(_xlfn.XLOOKUP(TRIM($E9),TRIM('Año 2026'!$E$3:$E$66),'Año 2026'!$K$3:$K$66),"")} | AK9: {=IFERROR(_xlfn.XLOOKUP(TRIM($E9),TRIM('Año 2026'!$E$3:$E$66),'Año 2026'!$L$3:$L$66),"")} | AL9: {=IFERROR(_xlfn.XLOOKUP(TRIM($E9),TRIM('Año 2026'!$E$3:$E$66),'Año 2026'!$M$3:$M$66),"")} | AM9: {=IFERROR(_xlfn.XLOOKUP(TRIM($E9),TRIM('Año 2026'!$E$3:$E$66),'Año 2026'!$N$3:$N$66),"")} | AN9: {=IFERROR(_xlfn.XLOOKUP(TRIM($E9),TRIM('Año 2026'!$E$3:$E$66),'Año 2026'!$O$3:$O$66),"")} | AO9: {=IFERROR(_xlfn.XLOOKUP(TRIM($E9),TRIM('Año 2026'!$E$3:$E$66),'Año 2026'!$P$3:$P$66),"")} | AP9: {=IFERROR(_xlfn.XLOOKUP(TRIM($E9),TRIM('Año 2026'!$E$3:$E$66),'Año 2026'!$Q$3:$Q$66),"")} | AQ9: {=IFERROR(_xlfn.XLOOKUP(TRIM($E9),TRIM('Año 2026'!$E$3:$E$66),'Año 2026'!$R$3:$R$66),"")} | AR9: {=IFERROR(_xlfn.XLOOKUP(TRIM($E9),TRIM('Año 2026'!$E$3:$E$66),'Año 2026'!$S$3:$S$66),"")} | AS9: {=IFERROR(_xlfn.XLOOKUP(TRIM($E9),TRIM('Año 2026'!$E$3:$E$66),'Año 2026'!$T$3:$T$66),"")} | AT9: {=IFERROR(_xlfn.XLOOKUP(TRIM($E9),TRIM('Año 2026'!$E$3:$E$66),'Año 2026'!$U$3:$U$66),"")} | AU9: {=IFERROR(_xlfn.XLOOKUP(TRIM($E9),TRIM('Año 2026'!$E$3:$E$66),'Año 2026'!$V$3:$V$66),"")} | AV9: {=IFERROR(_xlfn.XLOOKUP(TRIM($E9),TRIM('Año 2026'!$E$3:$E$66),'Año 2026'!$W$3:$W$66),"")} | AW9: {=IFERROR(_xlfn.XLOOKUP(TRIM($E9),TRIM('Año 2026'!$E$3:$E$66),'Año 2026'!$X$3:$X$66),"")} | AX9: {=IFERROR(_xlfn.XLOOKUP(TRIM($E9),TRIM('Año 2026'!$E$3:$E$66),'Año 2026'!$Y$3:$Y$66),"")} | AY9: {=IFERROR(_xlfn.XLOOKUP(TRIM($E9),TRIM('Año 2026'!$E$3:$E$66),'Año 2026'!$Z$3:$Z$66),"")} | AZ9: {=IFERROR(_xlfn.XLOOKUP(TRIM($E9),TRIM('Año 2026'!$E$3:$E$66),'Año 2026'!$AA$3:$AA$66),"")} | BA9: {=IFERROR(_xlfn.XLOOKUP(TRIM($E9),TRIM('Año 2026'!$E$3:$E$66),'Año 2026'!$AB$3:$AB$66),"")} | BB9: {=IFERROR(_xlfn.XLOOKUP(TRIM($E9),TRIM('Año 2026'!$E$3:$E$66),'Año 2026'!$AC$3:$AC$66),"")} | BC9: {=IFERROR(_xlfn.XLOOKUP(TRIM($E9),TRIM('Año 2026'!$E$3:$E$66),'Año 2026'!$AD$3:$AD$66),"")}
A10: 9 | B10: 2024 | C10: Denuncia | D10: Web | E10: 02805-2024-SUNEDU/02-13 | F10: En trámite | G10: 2024EXT0000048324-SUNEDU | H10: 44 | I10: Pública | K10: Lima | L10: Barranca | M10: Barranca | N10: Avenida Toribio Luzuriaga N° 376, Mz. J - Urbanización La Florida | O10: MLI | P10: IV | R10: Solicita se designe a una nueva vicepresidenta de investigación, debido a que en el transcurso del presente año, la universidad no vendría financiando proyectos de tesis, investigaciones de docentes, emprendimientos empresariales, ni grupos de investigación; con lo cual, se estaría incumpliendo las condiciones básicas de calidad. | S10: BAJA | T10: 1 | U10: La Universidad remitió información solicitada mediante Oficio N° 551-2025-UNAB-CO/ | V10: 45988 | W10: Por lo tanto se sugiere sea derivado a el especialista de Investigacion. Pendiente elaboración de Oficio de Requerimiento Inicial Se cuenta con un Informe N° ​2 – Orden de servicio N° 2036-2025​ de Maria Alejandra Fuentes Diestra, sobre la denuncia de Investigacion, donde considera informacion del Oficio N° 551-2025-UNAB-CO/P, donde se encuentran los enlaces de Investigación. | Y10: Pendiente revisión por Isabel Astete Desde el 04.02.26 al 20.02.26 Priorizada para ser cerrada en febrero 2026. | Z10: Sí | AA10: 46073 | AB10: =IF(AA10<TODAY(),"VENCIDO","POR VENCER") -> VENCIDO | AC10: 46080 | AD10: EN PROCESO | AE10: Carta y/o Oficio | AF10: {=IFERROR(_xlfn.XLOOKUP(TRIM($E10),TRIM('Año 2026'!$E$3:$E$66),'Año 2026'!$G$3:$G$66),"")} | AG10: {=IFERROR(_xlfn.XLOOKUP(TRIM($E10),TRIM('Año 2026'!$E$3:$E$66),'Año 2026'!$H$3:$H$66),"")} | AH10: {=IFERROR(_xlfn.XLOOKUP(TRIM($E10),TRIM('Año 2026'!$E$3:$E$66),'Año 2026'!$I$3:$I$66),"")} | AI10: {=IFERROR(_xlfn.XLOOKUP(TRIM($E10),TRIM('Año 2026'!$E$3:$E$66),'Año 2026'!$J$3:$J$66),"")} | AJ10: {=IFERROR(_xlfn.XLOOKUP(TRIM($E10),TRIM('Año 2026'!$E$3:$E$66),'Año 2026'!$K$3:$K$66),"")} | AK10: {=IFERROR(_xlfn.XLOOKUP(TRIM($E10),TRIM('Año 2026'!$E$3:$E$66),'Año 2026'!$L$3:$L$66),"")} | AL10: {=IFERROR(_xlfn.XLOOKUP(TRIM($E10),TRIM('Año 2026'!$E$3:$E$66),'Año 2026'!$M$3:$M$66),"")} | AM10: {=IFERROR(_xlfn.XLOOKUP(TRIM($E10),TRIM('Año 2026'!$E$3:$E$66),'Año 2026'!$N$3:$N$66),"")} | AN10: {=IFERROR(_xlfn.XLOOKUP(TRIM($E10),TRIM('Año 2026'!$E$3:$E$66),'Año 2026'!$O$3:$O$66),"")} | AO10: {=IFERROR(_xlfn.XLOOKUP(TRIM($E10),TRIM('Año 2026'!$E$3:$E$66),'Año 2026'!$P$3:$P$66),"")} | AP10: {=IFERROR(_xlfn.XLOOKUP(TRIM($E10),TRIM('Año 2026'!$E$3:$E$66),'Año 2026'!$Q$3:$Q$66),"")} | AQ10: {=IFERROR(_xlfn.XLOOKUP(TRIM($E10),TRIM('Año 2026'!$E$3:$E$66),'Año 2026'!$R$3:$R$66),"")} | AR10: {=IFERROR(_xlfn.XLOOKUP(TRIM($E10),TRIM('Año 2026'!$E$3:$E$66),'Año 2026'!$S$3:$S$66),"")} | AS10: {=IFERROR(_xlfn.XLOOKUP(TRIM($E10),TRIM('Año 2026'!$E$3:$E$66),'Año 2026'!$T$3:$T$66),"")} | AT10: {=IFERROR(_xlfn.XLOOKUP(TRIM($E10),TRIM('Año 2026'!$E$3:$E$66),'Año 2026'!$U$3:$U$66),"")} | AU10: {=IFERROR(_xlfn.XLOOKUP(TRIM($E10),TRIM('Año 2026'!$E$3:$E$66),'Año 2026'!$V$3:$V$66),"")} | AV10: {=IFERROR(_xlfn.XLOOKUP(TRIM($E10),TRIM('Año 2026'!$E$3:$E$66),'Año 2026'!$W$3:$W$66),"")} | AW10: {=IFERROR(_xlfn.XLOOKUP(TRIM($E10),TRIM('Año 2026'!$E$3:$E$66),'Año 2026'!$X$3:$X$66),"")} | AX10: {=IFERROR(_xlfn.XLOOKUP(TRIM($E10),TRIM('Año 2026'!$E$3:$E$66),'Año 2026'!$Y$3:$Y$66),"")} | AY10: {=IFERROR(_xlfn.XLOOKUP(TRIM($E10),TRIM('Año 2026'!$E$3:$E$66),'Año 2026'!$Z$3:$Z$66),"")} | AZ10: {=IFERROR(_xlfn.XLOOKUP(TRIM($E10),TRIM('Año 2026'!$E$3:$E$66),'Año 2026'!$AA$3:$AA$66),"")} | BA10: {=IFERROR(_xlfn.XLOOKUP(TRIM($E10),TRIM('Año 2026'!$E$3:$E$66),'Año 2026'!$AB$3:$AB$66),"")} | BB10: {=IFERROR(_xlfn.XLOOKUP(TRIM($E10),TRIM('Año 2026'!$E$3:$E$66),'Año 2026'!$AC$3:$AC$66),"")} | BC10: {=IFERROR(_xlfn.XLOOKUP(TRIM($E10),TRIM('Año 2026'!$E$3:$E$66),'Año 2026'!$AD$3:$AD$66),"")}
A11: 10 | B11: 2023 | C11: SNP | D11: No programada - oficio | E11: 00052-2023-SUNEDU/02-13 | F11: En trámite | H11: 30 | I11: Pública | J11: SL03, SL04, F01L01 | K11: SL03, SL04: Ayacucho | F01L01: Cusco | L11: SL03, SL04: Huamanga | F01L01: La Convención | M11: SL03, SL04: Ayacucho | F01L01: Pichari | N11: SL03 | SL04 | F01L01 | O11: MLI | P11: III, V, VI | Q11: 17, 19, 20, 21, 22, 27, 28, 30, 39, 40, 43, 44, 48 | R11: Caso referido a presuntas deficiencias en la infraestructura, equipamiento y servicios complementarios de la Universidad Nacional de San Cristóbal de Huamanga, tanto en la sede principal como en la filial La Convención – Pichari (local F01L01), consistentes en condiciones de inhabitabilidad de ambientes académicos, deficiencias de seguridad en instalaciones (luminarias deterioradas, conexiones expuestas y falta de ventilación), carencias en los servicios de salud universitarios, limitaciones en la operatividad del comedor universitario y de la residencia estudiantil, así como la ausencia de cerco perimétrico adecuado en la filial. Asimismo, se reporta insuficiencia de personal docente en determinados programas académicos y la falta de acreditación vigente del derecho de uso del local F01L01. | S11: ALTA | T11: 2 | U11: Respuesta por parte de la Universidad a los requerimientos realizados en el Acta de Supervisión, mediante Oficio N° 542-2025-UNSCH-R del 11.12.25 | V11: 46002 | W11: Está pendiente la elaboración del Informe de Resultados, ya que se recopiló información en el 2023 y en el 2025. | Y11: IR Antecedentes Barzen Manrique CBC III Carla La Torre 01.04.26 al 15.04.26 CBC V y VI 02.03.26 al 13.03.26 Priorizada para ser cerrada en abril 2026 | Z11: Sí | AA11: 46129 | AB11: =IF(AA11<TODAY(),"VENCIDO","POR VENCER") -> VENCIDO | AC11: 46136 | AD11: EN PROCESO | AE11: Informe de Resultados | AF11: {=IFERROR(_xlfn.XLOOKUP(TRIM($E11),TRIM('Año 2026'!$E$3:$E$66),'Año 2026'!$G$3:$G$66),"")} | AG11: {=IFERROR(_xlfn.XLOOKUP(TRIM($E11),TRIM('Año 2026'!$E$3:$E$66),'Año 2026'!$H$3:$H$66),"")} | AH11: {=IFERROR(_xlfn.XLOOKUP(TRIM($E11),TRIM('Año 2026'!$E$3:$E$66),'Año 2026'!$I$3:$I$66),"")} | AI11: {=IFERROR(_xlfn.XLOOKUP(TRIM($E11),TRIM('Año 2026'!$E$3:$E$66),'Año 2026'!$J$3:$J$66),"")} | AJ11: {=IFERROR(_xlfn.XLOOKUP(TRIM($E11),TRIM('Año 2026'!$E$3:$E$66),'Año 2026'!$K$3:$K$66),"")} | AK11: {=IFERROR(_xlfn.XLOOKUP(TRIM($E11),TRIM('Año 2026'!$E$3:$E$66),'Año 2026'!$L$3:$L$66),"")} | AL11: {=IFERROR(_xlfn.XLOOKUP(TRIM($E11),TRIM('Año 2026'!$E$3:$E$66),'Año 2026'!$M$3:$M$66),"")} | AM11: {=IFERROR(_xlfn.XLOOKUP(TRIM($E11),TRIM('Año 2026'!$E$3:$E$66),'Año 2026'!$N$3:$N$66),"")} | AN11: {=IFERROR(_xlfn.XLOOKUP(TRIM($E11),TRIM('Año 2026'!$E$3:$E$66),'Año 2026'!$O$3:$O$66),"")} | AO11: {=IFERROR(_xlfn.XLOOKUP(TRIM($E11),TRIM('Año 2026'!$E$3:$E$66),'Año 2026'!$P$3:$P$66),"")} | AP11: {=IFERROR(_xlfn.XLOOKUP(TRIM($E11),TRIM('Año 2026'!$E$3:$E$66),'Año 2026'!$Q$3:$Q$66),"")} | AQ11: {=IFERROR(_xlfn.XLOOKUP(TRIM($E11),TRIM('Año 2026'!$E$3:$E$66),'Año 2026'!$R$3:$R$66),"")} | AR11: {=IFERROR(_xlfn.XLOOKUP(TRIM($E11),TRIM('Año 2026'!$E$3:$E$66),'Año 2026'!$S$3:$S$66),"")} | AS11: {=IFERROR(_xlfn.XLOOKUP(TRIM($E11),TRIM('Año 2026'!$E$3:$E$66),'Año 2026'!$T$3:$T$66),"")} | AT11: {=IFERROR(_xlfn.XLOOKUP(TRIM($E11),TRIM('Año 2026'!$E$3:$E$66),'Año 2026'!$U$3:$U$66),"")} | AU11: {=IFERROR(_xlfn.XLOOKUP(TRIM($E11),TRIM('Año 2026'!$E$3:$E$66),'Año 2026'!$V$3:$V$66),"")} | AV11: {=IFERROR(_xlfn.XLOOKUP(TRIM($E11),TRIM('Año 2026'!$E$3:$E$66),'Año 2026'!$W$3:$W$66),"")} | AW11: {=IFERROR(_xlfn.XLOOKUP(TRIM($E11),TRIM('Año 2026'!$E$3:$E$66),'Año 2026'!$X$3:$X$66),"")} | AX11: {=IFERROR(_xlfn.XLOOKUP(TRIM($E11),TRIM('Año 2026'!$E$3:$E$66),'Año 2026'!$Y$3:$Y$66),"")} | AY11: {=IFERROR(_xlfn.XLOOKUP(TRIM($E11),TRIM('Año 2026'!$E$3:$E$66),'Año 2026'!$Z$3:$Z$66),"")} | AZ11: {=IFERROR(_xlfn.XLOOKUP(TRIM($E11),TRIM('Año 2026'!$E$3:$E$66),'Año 2026'!$AA$3:$AA$66),"")} | BA11: {=IFERROR(_xlfn.XLOOKUP(TRIM($E11),TRIM('Año 2026'!$E$3:$E$66),'Año 2026'!$AB$3:$AB$66),"")} | BB11: {=IFERROR(_xlfn.XLOOKUP(TRIM($E11),TRIM('Año 2026'!$E$3:$E$66),'Año 2026'!$AC$3:$AC$66),"")} | BC11: {=IFERROR(_xlfn.XLOOKUP(TRIM($E11),TRIM('Año 2026'!$E$3:$E$66),'Año 2026'!$AD$3:$AD$66),"")}
A12: 11 | B12: 2024 | C12: Denuncia | D12: Correo electrónico | E12: 01773-2024-SUNEDU/02-13 | F12: En trámite | G12: 2024EXT0000025963-SUNEDU | H12: 41 | I12: Pública | J12: SL01, SL02, SL03, SL04 | K12: La Libertad | L12: Sanchez Carrion | M12: Huamachuco | N12: Local SL01 Ramiro Priale N°540 Huamachuco (conducente a grado academico) | Local SL02 Garcilaso de la Vega N°905- Huamachuco. (conducente a grado academico) | Local SL03 ubicado en el centro de la ciudad de Huamachuco, cuyo uso es para fines administrativos | Local SL04, Av. Los Sauces, predio Unidad Catastral N°31527 denominado “Tantapusha”, ubicado al sur de la ciudad de Huamachuco, a | aproximadamente 5.3 km del local SL01. En dicho local, la Universidad construirá su nuevo campus universitario. | O12: MLI | P12: III, IV | Q12: 19, 27 | R12: El Sindicato de Trabajadores CAS de la Universidad Nacional Ciro Alegría, pone en conocimiento irregularidades a la oferta del servicio educativo: Sindicato de trabajadores de la UNCA solicitan la reconformacion de la comision organizadora por las siguientes razones: requerimientos mejora continua en instalaciones puesta en marcha de grupos electrogenos, ejecucion de proyectos CUI N°2471427, CUI:2509818, CUI:2511627 y CUI:2513857 en el local SL04 , evidencias de la implementacion de la infraestructura, maquinaria y equipos para el comedor universitario en el local SL04. (La denuncia refiere a los requerimientos que no han presentado la Universidad) | S12: ALTA | T12: 2 | U12: La Universidad presentó información con Oficio N° 0498-2025-UNCA/P-CO en respuesta al OFICIO N° 03963-2025-SUNEDU-DS-DIRESESU-UVE | V12: 45905 | W12: En la carpta Z se encuentra el OFICIO N° 03497-2025-SUNEDU-DS-DIRESESU-UVE (08.09.25), con el que se requirió información para 4 expedientes (01773-2024-SUNEDU/02-13, 01020-2025-SUNEDU/02-13, 01186-2025-SUNEDU/02-13 y 02160-2025-SUNEDU/02-13) y comunica que se realizará Visita de Inspección los dias 15 al 19 de setiembre a 5 locales. Isabel comenzó con la evaluación de la CBC IV el 10.02.26. | X12: MANUEL HURTADO | Y12: OS Antecedentes Barzen (Feb-26) CBC III Manuel Hurtado (Feb-26) CBC IV Liz (pendiente definir fechas) Priorizada para ser cerrada en julio 2026. | Z12: Sí | AA12: 46227 | AB12: =IF(AA12<TODAY(),"VENCIDO","POR VENCER") -> POR VENCER | AC12: 46234 | AD12: EN PROCESO | AE12: Carta y/o Oficio | AF12: {=IFERROR(_xlfn.XLOOKUP(TRIM($E12),TRIM('Año 2026'!$E$3:$E$66),'Año 2026'!$G$3:$G$66),"")} | AG12: {=IFERROR(_xlfn.XLOOKUP(TRIM($E12),TRIM('Año 2026'!$E$3:$E$66),'Año 2026'!$H$3:$H$66),"")} | AH12: {=IFERROR(_xlfn.XLOOKUP(TRIM($E12),TRIM('Año 2026'!$E$3:$E$66),'Año 2026'!$I$3:$I$66),"")} | AI12: {=IFERROR(_xlfn.XLOOKUP(TRIM($E12),TRIM('Año 2026'!$E$3:$E$66),'Año 2026'!$J$3:$J$66),"")} | AJ12: {=IFERROR(_xlfn.XLOOKUP(TRIM($E12),TRIM('Año 2026'!$E$3:$E$66),'Año 2026'!$K$3:$K$66),"")} | AK12: {=IFERROR(_xlfn.XLOOKUP(TRIM($E12),TRIM('Año 2026'!$E$3:$E$66),'Año 2026'!$L$3:$L$66),"")} | AL12: {=IFERROR(_xlfn.XLOOKUP(TRIM($E12),TRIM('Año 2026'!$E$3:$E$66),'Año 2026'!$M$3:$M$66),"")} | AM12: {=IFERROR(_xlfn.XLOOKUP(TRIM($E12),TRIM('Año 2026'!$E$3:$E$66),'Año 2026'!$N$3:$N$66),"")} | AN12: {=IFERROR(_xlfn.XLOOKUP(TRIM($E12),TRIM('Año 2026'!$E$3:$E$66),'Año 2026'!$O$3:$O$66),"")} | AO12: {=IFERROR(_xlfn.XLOOKUP(TRIM($E12),TRIM('Año 2026'!$E$3:$E$66),'Año 2026'!$P$3:$P$66),"")} | AP12: {=IFERROR(_xlfn.XLOOKUP(TRIM($E12),TRIM('Año 2026'!$E$3:$E$66),'Año 2026'!$Q$3:$Q$66),"")} | AQ12: {=IFERROR(_xlfn.XLOOKUP(TRIM($E12),TRIM('Año 2026'!$E$3:$E$66),'Año 2026'!$R$3:$R$66),"")} | AR12: {=IFERROR(_xlfn.XLOOKUP(TRIM($E12),TRIM('Año 2026'!$E$3:$E$66),'Año 2026'!$S$3:$S$66),"")} | AS12: {=IFERROR(_xlfn.XLOOKUP(TRIM($E12),TRIM('Año 2026'!$E$3:$E$66),'Año 2026'!$T$3:$T$66),"")} | AT12: {=IFERROR(_xlfn.XLOOKUP(TRIM($E12),TRIM('Año 2026'!$E$3:$E$66),'Año 2026'!$U$3:$U$66),"")} | AU12: {=IFERROR(_xlfn.XLOOKUP(TRIM($E12),TRIM('Año 2026'!$E$3:$E$66),'Año 2026'!$V$3:$V$66),"")} | AV12: {=IFERROR(_xlfn.XLOOKUP(TRIM($E12),TRIM('Año 2026'!$E$3:$E$66),'Año 2026'!$W$3:$W$66),"")} | AW12: {=IFERROR(_xlfn.XLOOKUP(TRIM($E12),TRIM('Año 2026'!$E$3:$E$66),'Año 2026'!$X$3:$X$66),"")} | AX12: {=IFERROR(_xlfn.XLOOKUP(TRIM($E12),TRIM('Año 2026'!$E$3:$E$66),'Año 2026'!$Y$3:$Y$66),"")} | AY12: {=IFERROR(_xlfn.XLOOKUP(TRIM($E12),TRIM('Año 2026'!$E$3:$E$66),'Año 2026'!$Z$3:$Z$66),"")} | AZ12: {=IFERROR(_xlfn.XLOOKUP(TRIM($E12),TRIM('Año 2026'!$E$3:$E$66),'Año 2026'!$AA$3:$AA$66),"")} | BA12: {=IFERROR(_xlfn.XLOOKUP(TRIM($E12),TRIM('Año 2026'!$E$3:$E$66),'Año 2026'!$AB$3:$AB$66),"")} | BB12: {=IFERROR(_xlfn.XLOOKUP(TRIM($E12),TRIM('Año 2026'!$E$3:$E$66),'Año 2026'!$AC$3:$AC$66),"")} | BC12: {=IFERROR(_xlfn.XLOOKUP(TRIM($E12),TRIM('Año 2026'!$E$3:$E$66),'Año 2026'!$AD$3:$AD$66),"")}
A13: 12 | B13: 2024 | C13: Denuncia | D13: Web | E13: 01155-2024-SUNEDU/02-13 | F13: En trámite | G13: 2024EXT0000015663-SUNEDU, 2024EXT0000038187-SUNEDU | H13: 2 | I13: Pública | J13: SL02, SL08 | K13: Lima | L13: Lima | M13: Lima | N13: 1.-Av. Nicolas de Pierola N° 262 / Cañete 710, Lima | 2.-Jr. Iquique N°127, 129, distrito de Breña, Lima | O13: MLI | P13: III | Q13: 19, 27, 28, 29 | R13: Manifiesta que habría sido víctima de engaño por parte de la universidad antes de su postulación, ya que le habrían indicado que las clases de la carrera de Contabilidad y Economía iban a ser dictadas en la nueva sede Oquendo; sin embargo, tras haber ingresado le indicarían que las clases continuarían dictándose en la sede ubicada en la Avenida Nicolás de Piérola. Estan vinculados dos (2)denuncias: 1.-Irregularidades en la Av Nicolas de Pierola 2024EXT0000015663-SUNEDU, del 03/05/2024 (las carreras de Contabilidad y Economía, este año se hizo de manera oficial por sus redes y por el prospecto, entonces muchos gracias a ello postularon a dichas carreras con el fin de llevar sus clases en la sede Oquendo de la UNFV por temas de distancia y/o infraestructura moderna. Pero ahora al ser ingresantes se informa desde la facultad que las clases aún seguirán siendo en la antigua sede (Av. Nicolás de Piérola 262, Lima 15001) 2.- Irregularidades sede Iquique 2024EXT0000038187-SUNEDU, del 23/09/2024 ( 1. El espacio es demasiado pequeno para la cantidad de estudiantes que somos, y nuestra facultad en los 3 ultimos procesos de admision amplio las vacantes de manera significativa por lo cual ahora somos demasiado e incluso por ello tomamos clases en otras sedes como la de odontologia sede pueblo libre. Se nos dice desde hace tiempo, que hay una sede en construccion (Oquendo) pero hasta ahora no hay avances.) | S13: MEDIA | T13: 1 | U13: Mediante la Carta Nº 01239-2024-SUNEDU-DS-DIRESESU-UVE, la SUNEDU comunica al denunciante de las acciones que se han venido tomando. Mediante OFICIO Nº 00789-2024-SUNEDU-DS-DIRESESU-UVE del 11/11/24 se remite a la Muni de Breña el caso en cuanto a los pasos de escaleras | V13: 45614 | W13: Se le responde al denunciante que el local ubicado en Av. Néstor Gambeta Dpto. Mz. 85, Ventanilla, Callao, solicitó modificación de licencia el 1 de abril de 2024 | Y13: Pendiente visita del 18.02.26 al 20.02.26 por Carla La Torre + Néstor Ticse+ Víctor dela Cruz+ Abogada Falta programar producto Priorizada para ser cerrada en diciembre 2026. | AA13: 46374 | AB13: =IF(AA13<TODAY(),"VENCIDO","POR VENCER") -> POR VENCER | AC13: 46379 | AD13: EN PROCESO | AE13: Carta y/o Oficio | AF13: {=IFERROR(_xlfn.XLOOKUP(TRIM($E13),TRIM('Año 2026'!$E$3:$E$66),'Año 2026'!$G$3:$G$66),"")} -> OFICIO Nº 02249-2026-SUNEDU-DS-DIRESESU-UVE | AG13: {=IFERROR(_xlfn.XLOOKUP(TRIM($E13),TRIM('Año 2026'!$E$3:$E$66),'Año 2026'!$H$3:$H$66),"")} -> 0 | AH13: {=IFERROR(_xlfn.XLOOKUP(TRIM($E13),TRIM('Año 2026'!$E$3:$E$66),'Año 2026'!$I$3:$I$66),"")} -> 0 | AI13: {=IFERROR(_xlfn.XLOOKUP(TRIM($E13),TRIM('Año 2026'!$E$3:$E$66),'Año 2026'!$J$3:$J$66),"")} -> 0 | AJ13: {=IFERROR(_xlfn.XLOOKUP(TRIM($E13),TRIM('Año 2026'!$E$3:$E$66),'Año 2026'!$K$3:$K$66),"")} -> 0 | AK13: {=IFERROR(_xlfn.XLOOKUP(TRIM($E13),TRIM('Año 2026'!$E$3:$E$66),'Año 2026'!$L$3:$L$66),"")} -> 0 | AL13: {=IFERROR(_xlfn.XLOOKUP(TRIM($E13),TRIM('Año 2026'!$E$3:$E$66),'Año 2026'!$M$3:$M$66),"")} -> 0 | AM13: {=IFERROR(_xlfn.XLOOKUP(TRIM($E13),TRIM('Año 2026'!$E$3:$E$66),'Año 2026'!$N$3:$N$66),"")} -> 0 | AN13: {=IFERROR(_xlfn.XLOOKUP(TRIM($E13),TRIM('Año 2026'!$E$3:$E$66),'Año 2026'!$O$3:$O$66),"")} -> 0 | AO13: {=IFERROR(_xlfn.XLOOKUP(TRIM($E13),TRIM('Año 2026'!$E$3:$E$66),'Año 2026'!$P$3:$P$66),"")} -> 0 | AP13: {=IFERROR(_xlfn.XLOOKUP(TRIM($E13),TRIM('Año 2026'!$E$3:$E$66),'Año 2026'!$Q$3:$Q$66),"")} -> 0 | AQ13: {=IFERROR(_xlfn.XLOOKUP(TRIM($E13),TRIM('Año 2026'!$E$3:$E$66),'Año 2026'!$R$3:$R$66),"")} -> 0 | AR13: {=IFERROR(_xlfn.XLOOKUP(TRIM($E13),TRIM('Año 2026'!$E$3:$E$66),'Año 2026'!$S$3:$S$66),"")} -> 0 | AS13: {=IFERROR(_xlfn.XLOOKUP(TRIM($E13),TRIM('Año 2026'!$E$3:$E$66),'Año 2026'!$T$3:$T$66),"")} -> 0 | AT13: {=IFERROR(_xlfn.XLOOKUP(TRIM($E13),TRIM('Año 2026'!$E$3:$E$66),'Año 2026'!$U$3:$U$66),"")} -> 0 | AU13: {=IFERROR(_xlfn.XLOOKUP(TRIM($E13),TRIM('Año 2026'!$E$3:$E$66),'Año 2026'!$V$3:$V$66),"")} -> 0 | AV13: {=IFERROR(_xlfn.XLOOKUP(TRIM($E13),TRIM('Año 2026'!$E$3:$E$66),'Año 2026'!$W$3:$W$66),"")} -> 0 | AW13: {=IFERROR(_xlfn.XLOOKUP(TRIM($E13),TRIM('Año 2026'!$E$3:$E$66),'Año 2026'!$X$3:$X$66),"")} -> 0 | AX13: {=IFERROR(_xlfn.XLOOKUP(TRIM($E13),TRIM('Año 2026'!$E$3:$E$66),'Año 2026'!$Y$3:$Y$66),"")} -> 0 | AY13: {=IFERROR(_xlfn.XLOOKUP(TRIM($E13),TRIM('Año 2026'!$E$3:$E$66),'Año 2026'!$Z$3:$Z$66),"")} -> 0 | AZ13: {=IFERROR(_xlfn.XLOOKUP(TRIM($E13),TRIM('Año 2026'!$E$3:$E$66),'Año 2026'!$AA$3:$AA$66),"")} -> 0 | BA13: {=IFERROR(_xlfn.XLOOKUP(TRIM($E13),TRIM('Año 2026'!$E$3:$E$66),'Año 2026'!$AB$3:$AB$66),"")} -> 0 | BB13: {=IFERROR(_xlfn.XLOOKUP(TRIM($E13),TRIM('Año 2026'!$E$3:$E$66),'Año 2026'!$AC$3:$AC$66),"")} -> 0 | BC13: {=IFERROR(_xlfn.XLOOKUP(TRIM($E13),TRIM('Año 2026'!$E$3:$E$66),'Año 2026'!$AD$3:$AD$66),"")} -> 0
A14: 13 | B14: 2024 | C14: SNP | D14: No programada - oficio | E14: 00548-2024-SUNEDU/02-13 | F14: En trámite | H14: 36 | I14: Pública | J14: F04L01 | K14: Cajamarca | L14: Chota | M14: Chota | N14: Av. Agricultura 144 | O14: MLI | P14: III | Q14: 17 | R14: Caso referido a la vigencia del derecho de uso del local F04L01 de la Universidad Nacional de Cajamarca, ubicado en la filial Chota, debido a que el contrato de arrendamiento que sustentó el licenciamiento institucional habría vencido al 31 de diciembre de 2018, sin que se haya identificado documentación vigente que acredite el derecho de uso a favor de la universidad. Esta situación fue advertida en el marco de acciones de supervisión, al verificarse que el local continúa siendo utilizado para la prestación del servicio educativo sin contar con sustento registral actualizado. | S14: BAJA | T14: 1 | U14: Se emitió el segundo reiterativo de información, mediante Oficio N.° 01381-2025-SUNEDU-DS-DIRESESU-UVE del 24.04.25 | V14: 45771 | W14: La Universidad no ha remtido la información solicitada, el oficio fue elaborado por Isabel. Al buscar en Google, se indica que el local está "permanentemente cerrado"; sin embargo, se ha identificado en las redes sociales que ha habido actividad hasta noviembre de 2025. | Y14: Pendiente enviar tercer reiterativo de información Pendiente visita en abril 2 personas. Priorizada para ser cerrada en junio 2026. | Z14: Sí | AA14: 46192 | AB14: =IF(AA14<TODAY(),"VENCIDO","POR VENCER") -> POR VENCER | AC14: 46199 | AD14: EN PROCESO | AE14: Informe de Resultados | AF14: {=IFERROR(_xlfn.XLOOKUP(TRIM($E14),TRIM('Año 2026'!$E$3:$E$66),'Año 2026'!$G$3:$G$66),"")} | AG14: {=IFERROR(_xlfn.XLOOKUP(TRIM($E14),TRIM('Año 2026'!$E$3:$E$66),'Año 2026'!$H$3:$H$66),"")} | AH14: {=IFERROR(_xlfn.XLOOKUP(TRIM($E14),TRIM('Año 2026'!$E$3:$E$66),'Año 2026'!$I$3:$I$66),"")} | AI14: {=IFERROR(_xlfn.XLOOKUP(TRIM($E14),TRIM('Año 2026'!$E$3:$E$66),'Año 2026'!$J$3:$J$66),"")} | AJ14: {=IFERROR(_xlfn.XLOOKUP(TRIM($E14),TRIM('Año 2026'!$E$3:$E$66),'Año 2026'!$K$3:$K$66),"")} | AK14: {=IFERROR(_xlfn.XLOOKUP(TRIM($E14),TRIM('Año 2026'!$E$3:$E$66),'Año 2026'!$L$3:$L$66),"")} | AL14: {=IFERROR(_xlfn.XLOOKUP(TRIM($E14),TRIM('Año 2026'!$E$3:$E$66),'Año 2026'!$M$3:$M$66),"")} | AM14: {=IFERROR(_xlfn.XLOOKUP(TRIM($E14),TRIM('Año 2026'!$E$3:$E$66),'Año 2026'!$N$3:$N$66),"")} | AN14: {=IFERROR(_xlfn.XLOOKUP(TRIM($E14),TRIM('Año 2026'!$E$3:$E$66),'Año 2026'!$O$3:$O$66),"")} | AO14: {=IFERROR(_xlfn.XLOOKUP(TRIM($E14),TRIM('Año 2026'!$E$3:$E$66),'Año 2026'!$P$3:$P$66),"")} | AP14: {=IFERROR(_xlfn.XLOOKUP(TRIM($E14),TRIM('Año 2026'!$E$3:$E$66),'Año 2026'!$Q$3:$Q$66),"")} | AQ14: {=IFERROR(_xlfn.XLOOKUP(TRIM($E14),TRIM('Año 2026'!$E$3:$E$66),'Año 2026'!$R$3:$R$66),"")} | AR14: {=IFERROR(_xlfn.XLOOKUP(TRIM($E14),TRIM('Año 2026'!$E$3:$E$66),'Año 2026'!$S$3:$S$66),"")} | AS14: {=IFERROR(_xlfn.XLOOKUP(TRIM($E14),TRIM('Año 2026'!$E$3:$E$66),'Año 2026'!$T$3:$T$66),"")} | AT14: {=IFERROR(_xlfn.XLOOKUP(TRIM($E14),TRIM('Año 2026'!$E$3:$E$66),'Año 2026'!$U$3:$U$66),"")} | AU14: {=IFERROR(_xlfn.XLOOKUP(TRIM($E14),TRIM('Año 2026'!$E$3:$E$66),'Año 2026'!$V$3:$V$66),"")} | AV14: {=IFERROR(_xlfn.XLOOKUP(TRIM($E14),TRIM('Año 2026'!$E$3:$E$66),'Año 2026'!$W$3:$W$66),"")} | AW14: {=IFERROR(_xlfn.XLOOKUP(TRIM($E14),TRIM('Año 2026'!$E$3:$E$66),'Año 2026'!$X$3:$X$66),"")} | AX14: {=IFERROR(_xlfn.XLOOKUP(TRIM($E14),TRIM('Año 2026'!$E$3:$E$66),'Año 2026'!$Y$3:$Y$66),"")} | AY14: {=IFERROR(_xlfn.XLOOKUP(TRIM($E14),TRIM('Año 2026'!$E$3:$E$66),'Año 2026'!$Z$3:$Z$66),"")} | AZ14: {=IFERROR(_xlfn.XLOOKUP(TRIM($E14),TRIM('Año 2026'!$E$3:$E$66),'Año 2026'!$AA$3:$AA$66),"")} | BA14: {=IFERROR(_xlfn.XLOOKUP(TRIM($E14),TRIM('Año 2026'!$E$3:$E$66),'Año 2026'!$AB$3:$AB$66),"")} | BB14: {=IFERROR(_xlfn.XLOOKUP(TRIM($E14),TRIM('Año 2026'!$E$3:$E$66),'Año 2026'!$AC$3:$AC$66),"")} | BC14: {=IFERROR(_xlfn.XLOOKUP(TRIM($E14),TRIM('Año 2026'!$E$3:$E$66),'Año 2026'!$AD$3:$AD$66),"")}
